Workbook

Sheet Dashboard
B2: Today's Notora Due Dates | K2: Today's S2A Due Dates
B4: Today's Date | D4: =TODAY() -> 46275 | K4: Today's Date | L4: =TODAY() -> 46275
B6: 50% Design | D6: 100% IFR | E6: IFP | F6: IFC | K6: 50% Design | L6: 100% IFR | M6: IFP | N6: IFC
B7: =_xlfn.XLOOKUP($D$4,Design!$K$2:$K$130,Design!$A$2:$A$130, "Nothing Due",0,1) -> Nothing Due | D7: =C16 -> - | E7: =C17 -> - | F7: =C18 -> - | K7: =C28 -> - | L7: =C29 -> - | M7: =C30 -> - | N7: =C31 -> -
B8: =_xlfn.XLOOKUP($D$4,Design!$K$2:$K$130,Design!$A$2:$A$130, "Nothing Due",0,-1) -> Nothing Due | D8: =_xlfn.XLOOKUP($D$4,Design!$M$2:$M$151,Design!$A$2:$A$151, "Nothing Due",0,-1) -> Nothing Due | E8: =_xlfn.XLOOKUP($D$4,Design!$O$2:$O$151,Design!$A$2:$A$151, "Nothing Due",0,-1) -> Nothing Due | F8: =_xlfn.XLOOKUP($D$4,Design!Q2:Q151,Design!$A$2:$A$151, "Nothing Due",0,-1) -> Nothing Due | K8: =_xlfn.XLOOKUP($D$4,Design!$K$2:$K$151,Design!$A$2:$A$151, "Nothing Due",0,-1) -> Nothing Due | L8: =_xlfn.XLOOKUP($D$4,Design!$M$2:$M$151,Design!$A$2:$A$151, "Nothing Due",0,-1) -> Nothing Due | M8: =_xlfn.XLOOKUP($D$4,Design!$O$2:$O$151,Design!$A$2:$A$151, "Nothing Due",0,-1) -> Nothing Due | N8: =_xlfn.XLOOKUP($D$4,Design!W2:W151,Design!$A$2:$A$151, "Nothing Due",0,-1) -> Nothing Due
B10: Notora Due Dates
B13: Todays Date | D13: =TODAY() -> 46275
C15: =TODAY() -> 46275 | D15: =WORKDAY(D13,1) -> 46276 | E15: =WORKDAY(D15,1) -> 46279 | F15: =WORKDAY(E15,1) -> 46280 | G15: =WORKDAY(F15,1) -> 46281 | H15: =WORKDAY(G15,1) -> 46282 | I15: =WORKDAY(H15,1) -> 46283 | J15: =WORKDAY(I15,1) -> 46286 | K15: =WORKDAY(J15,1) -> 46287 | L15: =WORKDAY(K15,1) -> 46288 | ... N15: =WORKDAY(M15,1) -> 46290
B16: 50% Design | C16: =_xlfn.XLOOKUP(C15,Design!$K$2:$K$151,Design!$A$2:$A$151, "-",0,1) -> - | D16: =_xlfn.XLOOKUP(D15,Design!$K$2:$K$151,Design!$A$2:$A$151, "-",0,1) -> - | E16: =_xlfn.XLOOKUP(E15,Design!$K$2:$K$151,Design!$A$2:$A$151, "-",0,1) -> - | F16: =_xlfn.XLOOKUP(F15,Design!$K$2:$K$151,Design!$A$2:$A$151, "-",0,1) -> - | G16: =_xlfn.XLOOKUP(G15,Design!$K$2:$K$151,Design!$A$2:$A$151, "-",0,1) -> - | H16: =_xlfn.XLOOKUP(H15,Design!$K$2:$K$151,Design!$A$2:$A$151, "-",0,1) -> - | I16: =_xlfn.XLOOKUP(I15,Design!$K$2:$K$151,Design!$A$2:$A$151, "-",0,1) -> - | J16: =_xlfn.XLOOKUP(J15,Design!$K$2:$K$151,Design!$A$2:$A$151, "-",0,1) -> - | ... N16: =_xlfn.XLOOKUP(N15,Design!$K$2:$K$151,Design!$A$2:$A$151, "-",0,1) -> -
B17: 100% IFR | C17: =_xlfn.XLOOKUP(C15,Design!$M$2:$M$151,Design!$A$2:$A$151, "-",0,1) -> - | D17: =_xlfn.XLOOKUP(D15,Design!$M$2:$M$151,Design!$A$2:$A$151, "-",0,1) -> - | E17: =_xlfn.XLOOKUP(E15,Design!$M$2:$M$151,Design!$A$2:$A$151, "-",0,1) -> - | F17: =_xlfn.XLOOKUP(F15,Design!$M$2:$M$151,Design!$A$2:$A$151, "-",0,1) -> - | G17: =_xlfn.XLOOKUP(G15,Design!$M$2:$M$151,Design!$A$2:$A$151, "-",0,1) -> - | H17: =_xlfn.XLOOKUP(H15,Design!$M$2:$M$151,Design!$A$2:$A$151, "-",0,1) -> - | I17: =_xlfn.XLOOKUP(I15,Design!$M$2:$M$151,Design!$A$2:$A$151, "-",0,1) -> - | J17: =_xlfn.XLOOKUP(J15,Design!$M$2:$M$151,Design!$A$2:$A$151, "-",0,1) -> - | ... N17: =_xlfn.XLOOKUP(N15,Design!$M$2:$M$151,Design!$A$2:$A$151, "-",0,1) -> -
B18: IFP | C18: =_xlfn.XLOOKUP(C15,Design!$O$2:$O$151,Design!$A$2:$A$151, "-",0,1) -> - | D18: =_xlfn.XLOOKUP(D15,Design!$O$2:$O$151,Design!$A$2:$A$151, "-",0,1) -> - | E18: =_xlfn.XLOOKUP(E15,Design!$O$2:$O$151,Design!$A$2:$A$151, "-",0,1) -> - | F18: =_xlfn.XLOOKUP(F15,Design!$O$2:$O$151,Design!$A$2:$A$151, " - ",0,1) -> - | G18: =_xlfn.XLOOKUP(G15,Design!$O$2:$O$151,Design!$A$2:$A$151, "-",0,1) -> - | H18: =_xlfn.XLOOKUP(H15,Design!$O$2:$O$151,Design!$A$2:$A$151, "-",0,1) -> - | I18: =_xlfn.XLOOKUP(I15,Design!$O$2:$O$151,Design!$A$2:$A$151, "-",0,1) -> - | J18: =_xlfn.XLOOKUP(J15,Design!$O$2:$O$151,Design!$A$2:$A$151, "-",0,1) -> - | K18: =_xlfn.XLOOKUP(K15,Design!$O$2:$O$151,Design!$A$2:$A$151, "-",0,1) -> - | L18: =_xlfn.XLOOKUP(L15,Design!$O$2:$O$151,Design!$A$2:$A$151, "-",0,1) -> - | M18: =_xlfn.XLOOKUP(M15,Design!$O$2:$O$151,Design!$A$2:$A$151, "-",0,1) -> - | N18: =_xlfn.XLOOKUP(N15,Design!$O$2:$O$151,Design!$A$2:$A$151, "-",0,1) -> -
B19: IFC | C19: =_xlfn.XLOOKUP(C15,Design!$Q$2:$Q$151,Design!$A$2:$A$151, "-",0,1) -> - | D19: =_xlfn.XLOOKUP(D15,Design!$Q$2:$Q$151,Design!$A$2:$A$151, "-",0,1) -> - | E19: =_xlfn.XLOOKUP(E15,Design!$Q$2:$Q$151,Design!$A$2:$A$151, "-",0,1) -> - | F19: =_xlfn.XLOOKUP(F15,Design!$Q$2:$Q$151,Design!$A$2:$A$151, "-",0,1) -> - | G19: =_xlfn.XLOOKUP(G15,Design!$Q$2:$Q$151,Design!$A$2:$A$151, "-",0,1) -> - | H19: =_xlfn.XLOOKUP(H15,Design!$Q$2:$Q$151,Design!$A$2:$A$151, "-",0,1) -> - | I19: =_xlfn.XLOOKUP(I15,Design!$Q$2:$Q$151,Design!$A$2:$A$151, "-",0,1) -> - | J19: =_xlfn.XLOOKUP(J15,Design!$Q$2:$Q$151,Design!$A$2:$A$151, "-",0,1) -> - | ... N19: =_xlfn.XLOOKUP(N15,Design!$Q$2:$Q$151,Design!$A$2:$A$151, "-",0,1) -> -
B21: S2A Due Dates
B24: Todays Date | D24: =TODAY() -> 46275
C26: =TODAY() -> 46275 | D26: =WORKDAY(D24,1) -> 46276 | E26: =WORKDAY(D26,1) -> 46279 | F26: =WORKDAY(E26,1) -> 46280 | G26: =WORKDAY(F26,1) -> 46281 | H26: =WORKDAY(G26,1) -> 46282 | I26: =WORKDAY(H26,1) -> 46283 | J26: =WORKDAY(I26,1) -> 46286 | K26: =WORKDAY(J26,1) -> 46287 | L26: =WORKDAY(K26,1) -> 46288 | ... N26: =WORKDAY(M26,1) -> 46290
B27: Floor Plans | C27: =_xlfn.XLOOKUP(C26,Design!$J$2:$J$151,Design!$A$2:$A$151, " - ",0,1) -> - | D27: =_xlfn.XLOOKUP(D26,Design!$J$2:$J$151,Design!$A$2:$A$151, " - ",0,1) -> - | E27: =_xlfn.XLOOKUP(E26,Design!$J$2:$J$151,Design!$A$2:$A$151, " - ",0,1) -> - | F27: =_xlfn.XLOOKUP(F26,Design!$J$2:$J$151,Design!$A$2:$A$151, " - ",0,1) -> - | G27: =_xlfn.XLOOKUP(G26,Design!$J$2:$J$151,Design!$A$2:$A$151, " - ",0,1) -> - | H27: =_xlfn.XLOOKUP(H26,Design!$J$2:$J$151,Design!$A$2:$A$151, " - ",0,1) -> - | I27: =_xlfn.XLOOKUP(I26,Design!$J$2:$J$151,Design!$A$2:$A$151, " - ",0,1) -> - | J27: =_xlfn.XLOOKUP(J26,Design!$J$2:$J$151,Design!$A$2:$A$151, " - ",0,1) -> - | ... N27: =_xlfn.XLOOKUP(N26,Design!$J$2:$J$151,Design!$A$2:$A$151, " - ",0,1) -> -
B28: 50% Design | C28: =_xlfn.XLOOKUP(C26,Design!$L$2:$L$151,Design!$A$2:$A$151, " - ",0,1) -> - | D28: =_xlfn.XLOOKUP(D26,Design!$L$2:$L$151,Design!$A$2:$A$151, " - ",0,1) -> - | E28: =_xlfn.XLOOKUP(E26,Design!$L$2:$L$151,Design!$A$2:$A$151, " - ",0,1) -> - | F28: =_xlfn.XLOOKUP(F26,Design!$L$2:$L$151,Design!$A$2:$A$151, " - ",0,1) -> - | G28: =_xlfn.XLOOKUP(G26,Design!$L$2:$L$151,Design!$A$2:$A$151, " - ",0,1) -> - | H28: =_xlfn.XLOOKUP(H26,Design!$L$2:$L$151,Design!$A$2:$A$151, " - ",0,1) -> - | I28: =_xlfn.XLOOKUP(I26,Design!$L$2:$L$151,Design!$A$2:$A$151, " - ",0,1) -> - | J28: =_xlfn.XLOOKUP(J26,Design!$L$2:$L$151,Design!$A$2:$A$151, " - ",0,1) -> - | ... N28: =_xlfn.XLOOKUP(N26,Design!$L$2:$L$151,Design!$A$2:$A$151, " - ",0,1) -> -
B29: 100% IFR | C29: =_xlfn.XLOOKUP(C26,Design!$N$2:$N$151,Design!$A$2:$A$151, "-",0,1) -> - | D29: =_xlfn.XLOOKUP(D26,Design!$N$2:$N$151,Design!$A$2:$A$151, "-",0,1) -> - | E29: =_xlfn.XLOOKUP(E26,Design!$N$2:$N$151,Design!$A$2:$A$151, "-",0,1) -> - | F29: =_xlfn.XLOOKUP(F26,Design!$N$2:$N$151,Design!$A$2:$A$151, "-",0,1) -> - | G29: =_xlfn.XLOOKUP(G26,Design!$N$2:$N$151,Design!$A$2:$A$151, "-",0,1) -> - | H29: =_xlfn.XLOOKUP(H26,Design!$N$2:$N$151,Design!$A$2:$A$151, "-",0,1) -> - | I29: =_xlfn.XLOOKUP(I26,Design!$N$2:$N$151,Design!$A$2:$A$151, "-",0,1) -> - | J29: =_xlfn.XLOOKUP(J26,Design!$N$2:$N$151,Design!$A$2:$A$151, "-",0,1) -> - | ... N29: =_xlfn.XLOOKUP(N26,Design!$N$2:$N$151,Design!$A$2:$A$151, "-",0,1) -> -
B30: IFP | C30: =_xlfn.XLOOKUP(C26,Design!$P$2:$P$151,Design!$A$2:$A$151, "-",0,1) -> - | D30: =_xlfn.XLOOKUP(D26,Design!$P$2:$P$151,Design!$A$2:$A$151, "-",0,1) -> - | E30: =_xlfn.XLOOKUP(E26,Design!$P$2:$P$151,Design!$A$2:$A$151, "-",0,1) -> - | F30: =_xlfn.XLOOKUP(F26,Design!$P$2:$P$151,Design!$A$2:$A$151, "-",0,1) -> - | G30: =_xlfn.XLOOKUP(G26,Design!$P$2:$P$151,Design!$A$2:$A$151, "-",0,1) -> - | H30: =_xlfn.XLOOKUP(H26,Design!$P$2:$P$151,Design!$A$2:$A$151, "-",0,1) -> - | I30: =_xlfn.XLOOKUP(I26,Design!$P$2:$P$151,Design!$A$2:$A$151, "-",0,1) -> - | J30: =_xlfn.XLOOKUP(J26,Design!$P$2:$P$151,Design!$A$2:$A$151, "-",0,1) -> - | ... N30: =_xlfn.XLOOKUP(N26,Design!$P$2:$P$151,Design!$A$2:$A$151, "-",0,1) -> -
B31: IFC | C31: =_xlfn.XLOOKUP(C26,Design!$Q$2:$Q$151,Design!$A$2:$A$151, "-") -> - | D31: =_xlfn.XLOOKUP(D26,Design!$Q$2:$Q$151,Design!$A$2:$A$151, "-") -> - | E31: =_xlfn.XLOOKUP(E26,Design!$Q$2:$Q$151,Design!$A$2:$A$151, "-") -> - | F31: =_xlfn.XLOOKUP(F26,Design!$Q$2:$Q$151,Design!$A$2:$A$151, "-") -> - | G31: =_xlfn.XLOOKUP(G26,Design!$Q$2:$Q$151,Design!$A$2:$A$151, "-") -> - | H31: =_xlfn.XLOOKUP(H26,Design!$Q$2:$Q$151,Design!$A$2:$A$151, "-") -> - | I31: =_xlfn.XLOOKUP(I26,Design!$Q$2:$Q$151,Design!$A$2:$A$151, "-") -> - | J31: =_xlfn.XLOOKUP(J26,Design!$Q$2:$Q$151,Design!$A$2:$A$151, "-") -> - | ... N31: =_xlfn.XLOOKUP(N26,Design!$Q$2:$Q$151,Design!$A$2:$A$151, "-") -> -
B32: Iss Record | C32: =_xlfn.XLOOKUP(C26,Design!$U$2:$U$151,Design!$A$2:$A$151, "-") -> - | D32: =_xlfn.XLOOKUP(D26,Design!$U$2:$U$151,Design!$A$2:$A$151, "-") -> - | E32: =_xlfn.XLOOKUP(E26,Design!$U$2:$U$151,Design!$A$2:$A$151, "-") -> - | G32: =_xlfn.XLOOKUP(G26,Design!$U$2:$U$151,Design!$A$2:$A$151, "-") -> - | H32: =_xlfn.XLOOKUP(H26,Design!$U$2:$U$151,Design!$A$2:$A$151, "-") -> - | I32: =_xlfn.XLOOKUP(I26,Design!$U$2:$U$151,Design!$A$2:$A$151, "-") -> - | J32: =_xlfn.XLOOKUP(J26,Design!$U$2:$U$151,Design!$A$2:$A$151, "-") -> - | K32: =_xlfn.XLOOKUP(K26,Design!$U$2:$U$151,Design!$A$2:$A$151, "-") -> - | L32: =_xlfn.XLOOKUP(L26,Design!$U$2:$U$151,Design!$A$2:$A$151, "-") -> - | M32: =_xlfn.XLOOKUP(M26,Design!$U$2:$U$151,Design!$A$2:$A$151, "-") -> - | N32: =_xlfn.XLOOKUP(N26,Design!$U$2:$U$151,Design!$A$2:$A$151, "-") -> -
B35: Past Due: | C35: 1D | D35: 2D | E35: 3D | F35: 4D | G35: 5D | H35: 6D | I35: 7D | J35: 8D | K35: 9D | L35: 10D | M35: 11D | N35: 12D
C36: =_xlfn.XLOOKUP($C$15-1,Design!$Q$2:$Q$151,Design!$A$2:$A$151, "-",0,1) -> - | D36: =_xlfn.XLOOKUP($C$15-2,Design!$Q$2:$Q$151,Design!$A$2:$A$151, "-",0,1) -> - | E36: =_xlfn.XLOOKUP($C$15-3,Design!$Q$2:$Q$151,Design!$A$2:$A$151, "-",0,1) -> - | F36: =_xlfn.XLOOKUP($C$15-4,Design!$Q$2:$Q$151,Design!$A$2:$A$151, "-",0,1) -> - | G36: =_xlfn.XLOOKUP($C$15-5,Design!$Q$2:$Q$151,Design!$A$2:$A$151, "-",0,1) -> - | H36: =_xlfn.XLOOKUP($C$15-6,Design!$Q$2:$Q$151,Design!$A$2:$A$151, "-",0,1) -> - | I36: =_xlfn.XLOOKUP($C$15-7,Design!$Q$2:$Q$151,Design!$A$2:$A$151, "-",0,1) -> - | J36: =_xlfn.XLOOKUP($C$15-8,Design!$Q$2:$Q$151,Design!$A$2:$A$151, "-",0,1) -> - | K36: =_xlfn.XLOOKUP($C$15-9,Design!$Q$2:$Q$151,Design!$A$2:$A$151, "-",0,1) -> - | L36: =_xlfn.XLOOKUP($C$15-10,Design!$Q$2:$Q$151,Design!$A$2:$A$151, "-",0,1) -> - | M36: =_xlfn.XLOOKUP($C$15-11,Design!$Q$2:$Q$151,Design!$A$2:$A$151, "-",0,1) -> - | N36: =_xlfn.XLOOKUP($C$15-12,Design!$Q$2:$Q$151,Design!$A$2:$A$151, "-",0,1) -> -

Sheet Info Needed
A2: 50% Design
A3: Address or Lat/Long
A4: Approved Floorplans
A5: Headend Location
A6: Parent or Child Site?
A7: Greenfield site?
A8: Project Specific Notes
A10: 90/100% CAD Set
A11: Packaging Preferences
A12: CAD Titleblock with Client Logo Images (dwg & jpgs)
A13: CAD Floor Plans of the building and The Site Plan or Survey (dwg files)
A14: Cover Sheet if/when available (dwg or pdf)
... A29: Any redlines/instructions for changes

Sheet Design-formattingv2
A1: NAME | B1: LOCATION | C1: A/E | D1: Phase (Design or CA) | E1: AE-PM Name | F1: AE-PM Contact | G1: S2 PM | H1: Project Status | I1: Floorplans Received | J1: Floor Plans Needed | K1: 50% IFR - Notora | L1: 50% IFR - AE | M1: 100% IFR - Notora | N1: 100% IFR - AE | O1: IFP - Notora | P1: IFP - AE | Q1: IFC | R1: Project Start | S1: Submittal | T1: Substantial Completion | U1: Issue For Record | V1: Completion | W1: Commissioning | X1: Action Item Needed | Y1: Comments
A2: ATL06 | B2: Atlanta | C2: Highland Associates | D2: Design | E2: Christopher Ritchie | F2: critchie@ha-ny.com | H2: A | I2: Supposed to be 4/7/2023 | J2: =IFERROR(WORKDAY(Table145[[#This Row],[50% IFR - AE]],-15), " ") | K2: Complete | M2: No Notora | N2: 10/3/2023- Complete | O2: No Notora | P2: 10/24/2023-Complete | Q2: 2/12/2024-complete | X2: Need to track down: Floor Plans, AHJ (Authorities having jurisdiction contact), enforced code | Y2: Location: East Point GA Lat Long: 33*38'30"N, 84*30'59"W FloorPlans to be updated Friday the 7th
A3: ATL07 | H3: A | J3: 5/13/2024-complete | K3: 45435 | L3: 45436 | N3: 45468
A4: AVC02 | H4: A | J4: =IFERROR(WORKDAY(Table145[[#This Row],[50% IFR - AE]],-15), " ") | L4: 3/25/2024-Complete | N4: 4/29/2024-complete | P4: 45427 | V4: Need as-builts/testing for AVC01. Some weirdness w AVC01 | X4: DAS and Public safety Proposal needed.
A5: AVC17 | B5: SOUTH HILL, VA | C5: Highland Associates | D5: Design | E5: Hector Hernandez | F5: hhernandez@ha-ny.com | G5: Bram Wathen | H5: A | I5: 44981 | J5: =IFERROR(WORKDAY(Table145[[#This Row],[50% IFR - AE]],-15), " ") | K5: 3/8/2023 - complete | L5: 3/20/2023- complete | M5: 4/17/2023 - complete | N5: 4/24/2023 - complete | O5: 6/2/2023 - complete | P5: 6/5/2023 - complete | Q5: 8/3/2023-Complete | X5: Update the IFC Date | Y5: 3 Different Issues. Need to confrim if power supply for fiber optical master is required. Need ROIP specs, Site Heat map.
A6: AVC18 | B6: SOUTH HILL, VA | C6: Highland Associates | D6: Design | E6: Hector Hernandez | F6: hhernandez@ha-ny.com | G6: Bram Wathen | H6: A | I6: 44988 | J6: =IFERROR(WORKDAY(Table145[[#This Row],[50% IFR - AE]],-15), " ") | K6: 3/15/2023 - complete | L6: 3/20/2023 - complete | M6: 4/17/2023 - complete | N6: 4/24/2023 - complete | O6: 6/2/2023 - complete | P6: 6/5/2023 - complete | Q6: 8/3/2023-Complete | X6: Update the IFC Date | Y6: Review Drawings prior to IFP
A7: AVC43 | B7: SOUTH HILL, VA | C7: Swanson Rink | D7: Design | E7: Ryan Sims | F7: RSims@swansonrink.com | H7: C | I7: 44874 | J7: =IFERROR(WORKDAY(Table145[[#This Row],[50% IFR - AE]],-15), " ") | K7: Complete | L7: 11/21/2022 - Complete | M7: Complete | P7: Complete | X7: 2x2 cabinet
A8: CCO07 | H8: A | J8: =IFERROR(WORKDAY(Table145[[#This Row],[50% IFR - AE]],-15), " ") | K8: 8/23/2023 - complete | L8: 9/7/2023 - complete | M8: No Notora | N8: 10/19/2023-Complete | O8: No Notora | P8: 11/7/2023-Complete
A9: CHI05 | B9: Chicago | I9: 45065 | J9: =IFERROR(WORKDAY(Table145[[#This Row],[50% IFR - AE]],-15), " ") | K9: 5/26/2023 - complete | Q9: 45384 | U9: No Notora | Y9: We need NT proposal
A10: CHI11 | B10: Chicago | I10: X | J10: =IFERROR(WORKDAY(Table145[[#This Row],[50% IFR - AE]],-15), " ") | K10: 5/26/2023 - complete | P10: 3/11/2024-Complete | Y10: We need NT proposal
A11: CHI22 | B11: Chicago | H11: A | J11: =IFERROR(WORKDAY(Table145[[#This Row],[50% IFR - AE]],-15), " ") | P11: 1/11/2024-COMPLETE | Q11: 1/19/2024-complete | Y11: IFP DRB17 Print
A12: CLT04 | B12: North Carolina | C12: Olson | D12: Design | E12: David Barber | F12: dbarber@olsson.com | G12: Bram Wathen | H12: A | I12: 44957 | J12: =IFERROR(WORKDAY(Table145[[#This Row],[50% IFR - AE]],-15), " ") | K12: 2/16/2023 - complete | L12: 2/16/2023 - complete | M12: 4/12/2023 -complete | N12: 4/26/2023 - complete | O12: 2/20/2024-Complete | P12: 2/21/2024-Complete | X12: Title block updates. Request sent to Stephen 5/11 | Y12: Get address and find cell towers
A13: CLT10 | B13: North Carolina | C13: Olsson | D13: Design | E13: Meg Plank | F13: mplank@olsson.com | H13: A | I13: X | J13: =IFERROR(WORKDAY(Table145[[#This Row],[50% IFR - AE]],-15), " ") | K13: 6/30/2023 - Complete | L13: 7/06/2023 - Complete | M13: 8/25/2023 - complete | N13: 8/31/2023-Complete | O13: 2/20/2024-Complete | P13: 2/21/2024-Complete | X13: Site Plans & Floor Plans | Y13: Project Kick off June 1st.
A14: CLT11 | C14: Olson | D14: Design | E14: David Barber | F14: dbarber@olsson.com | G14: Bram Wathen | H14: P | J14: =IFERROR(WORKDAY(Table145[[#This Row],[50% IFR - AE]],-15), " ")
A15: CLT17 | C15: Olson | D15: Design | E15: David Barber | F15: dbarber@olsson.com | G15: Bram Wathen | H15: P | I15: X | J15: =IFERROR(WORKDAY(Table145[[#This Row],[50% IFR - AE]],-15), " ") | K15: 45240 | L15: 11/16/2023-complete | M15: 45280 | N15: 1/3/2024-Complete | P15: 2/14/2024-Complete | Y15: Not doing the CADs for this one
A16: CPQ03 | B16: BRAZIL | C16: Deerns | D16: Design | E16: Gabriel Pereira | F16: gabriel.pereira@deerns.com | H16: C | J16: =IFERROR(WORKDAY(Table145[[#This Row],[50% IFR - AE]],-15), " ") | Q16: 45215
A17: CPQ07 | B17: BRAZIL | C17: Deerns | D17: Design | E17: Gabriel Pereira | F17: gabriel.pereira@deerns.com | H17: C | I17: X | J17: =IFERROR(WORKDAY(Table145[[#This Row],[50% IFR - AE]],-15), " ") | K17: 2/17/2023 - complete | L17: 1/11/2023 - Complete | X17: Need updated IFR Date, if we're doing the CAD's | Y17: 1/25: emailed Kelwin asking for info
A18: CPQ08 | J18: =IFERROR(WORKDAY(Table145[[#This Row],[50% IFR - AE]],-15), " ") | L18: 1/8/2024-Complete
A19: CPQ11 | B19: BRAZIL | C19: Deerns | D19: Design | E19: Gabriel Pereira | F19: gabriel.pereira@deerns.com | H19: C | I19: X | J19: =IFERROR(WORKDAY(Table145[[#This Row],[50% IFR - AE]],-15), " ") | K19: Complete
A20: CYS17 | B20: Cheyanne | C20: Jacobs | D20: Design | E20: Kristin McCue | F20: Kristin.McCue@jacobs.com | H20: C | J20: =IFERROR(WORKDAY(Table145[[#This Row],[50% IFR - AE]],-15), " ") | M20: Complete | N20: 1/24/2023-complete | O20: complete | P20: complete | X20: IFP from WT | Y20: 2/6/2023: WT indicates a 2/13 delivery date. 2/6/2023: emailed WT requesting IFP update 1/24: recieved updated design fromWT, uploaded 1/20: recieved design from David. Emailed AE the drawing list and uploaded files to AE and S2 1/19: This is a 'WT' site, emailed Davide requesting design update 1/18: sent philip design pkg 4 email 1/13/23: emailed Kristen requesting update
A21: DFW20 | J21: =IFERROR(WORKDAY(Table145[[#This Row],[50% IFR - AE]],-15), " ") | Q21: 3/8/2024-complete
A22: DSM12 | B22: DES MOINES | C22: Burns & McDonnell | D22: Design | E22: Kylie Hornbeck | F22: khornbeck@burnsmcd.com | H22: C | J22: =IFERROR(WORKDAY(Table145[[#This Row],[50% IFR - AE]],-15), " ") | X22: Nick coordinating with AE
A23: DSM14 | B23: DES MOINES | C23: Burns & McDonnell | D23: Design | E23: Kylie Hornbeck | F23: khornbeck@burnsmcd.com | H23: C | J23: =IFERROR(WORKDAY(Table145[[#This Row],[50% IFR - AE]],-15), " ") | X23: Nick coordinating with AE
A24: DSM15 | B24: DES MOINES | C24: Burns & McDonnell | D24: Design | E24: Kylie Hornbeck | F24: khornbeck@burnsmcd.com | H24: C | J24: =IFERROR(WORKDAY(Table145[[#This Row],[50% IFR - AE]],-15), " ") | X24: Need Floorplans & Schedule - Nick to follow up with AE
A25: DSM40 | B25: DES MOINES | C25: Burns & McDonnell | D25: Design | E25: Kylie Hornbeck | F25: khornbeck@burnsmcd.com | H25: C | J25: =IFERROR(WORKDAY(Table145[[#This Row],[50% IFR - AE]],-15), " ") | Q25: 5/8/2024-Complete | X25: Nick coordinating with AE
A26: DSM41 | B26: DES MOINES | C26: Burns & McDonnell | D26: Design | E26: Kylie Hornbeck | F26: khornbeck@burnsmcd.com | H26: C | J26: =IFERROR(WORKDAY(Table145[[#This Row],[50% IFR - AE]],-15), " ") | X26: Nick coordinating with AE
A27: EAT04 | B27: WEANATCHEE, WA | C27: ESD | D27: Design | E27: Chad Mendell | F27: cmendell@esdglobal.com | H27: C | J27: =IFERROR(WORKDAY(Table145[[#This Row],[50% IFR - AE]],-15), " ") | K27: Complete | L27: 12/1/2022 - Complete | M27: Complete | N27: 1/12/2023 - Complete | O27: 1/19/23-complete | P27: 1/26/2023-complete | Q27: 5/31/2023-Complete | Y27: 2/6/23: IFC is TBD no update1/25: recieved updated design from Philip, uploaded to AE and S2 1/19: recieved updated design from Philip, uploaded to BIM and S2 1/19: uploaded specs, requested IFP design from Philip 1/18: sent IFP instructions to Notora
A28: EAT05 | B28: WEANATCHEE, WA | C28: ESD | D28: Bid | E28: Chad Mendell | F28: cmendell@esdglobal.com | H28: A | I28: 45033 | J28: =IFERROR(WORKDAY(Table145[[#This Row],[50% IFR - AE]],-15), " ") | K28: 5/3/2023 - complete | L28: 4/20/2023 - complete | M28: 5/19/2023 - complete | N28: 5/25/2023 - complete | O28: complete | P28: 6/13/2023 - complete | Q28: 3/5/2024-Complete | X28: Notora Internal review return 5/1-5/2 | Y28: May
A29: EAT06 | H29: A | J29: =IFERROR(WORKDAY(Table145[[#This Row],[50% IFR - AE]],-15), " ") | K29: 8/9/2023--Complete | L29: 8/1/2023-Complete | N29: 9/7/2023 - complete | P29: 9/26/2023-Complete
A30: EAT09 | H30: A | I30: 8/16/2023? | J30: =IFERROR(WORKDAY(Table145[[#This Row],[50% IFR - AE]],-15), " ") | N30: 9/7/2023 - complete | P30: 9/26/2023-Complete
A31: EAT12 | B31: WEANATCHEE, WA | C31: ESD | D31: Design | E31: Chad Mendell | F31: cmendell@esdglobal.com | H31: A | J31: =IFERROR(WORKDAY(Table145[[#This Row],[50% IFR - AE]],-15), " ") | K31: 2/20/2023-complete | L31: 2/23/2023-complete | M31: 3/20/2023 - complete | N31: 3/9/2023 - complete | O31: complete | P31: 4/6/2023 - complete | Q31: 3/21/2024 Complete | X31: Change notes in the Public Safety. Cover the L1 containment unless AHJ approves alternate means and methods. Pull box detail | Y31: 2/15: in internal review 2/15: requested update from Notora 2/3/23: floor plan delivered to Notora 2/1: Harold got floorplans today; 1/18: Design is resuming with meeting 1/30
A32: EAT13 | B32: WEANATCHEE, WA | C32: ESD | D32: Design | E32: Chad Mendell | F32: cmendell@esdglobal.com | H32: A | I32: X | J32: =IFERROR(WORKDAY(Table145[[#This Row],[50% IFR - AE]],-15), " ") | K32: 6/14/2023 - complete | L32: 6/15/2023 - complete | M32: 7/18/2023-Complete | N32: 7/20/2023-Complete | O32: 8/1/2023-Complete | P32: 8/2/2023-Complete | Q32: 4/9/2024-complete | Y32: Starting the week of 5/8
A33: EAT14 | B33: WEANATCHEE, WA | H33: A | I33: X | J33: =IFERROR(WORKDAY(Table145[[#This Row],[50% IFR - AE]],-15), " ") | K33: 9/27/2023 - complete | L33: 9/21/2023 - Complete | M33: 10/27/2023-complete | N33: 11/28/2023-Complete | P33: 12/14/2023 - Complete | Q33: 45427 | X33: Battery backups, near far, L1 containement?
A34: FTY01 | J34: =IFERROR(WORKDAY(Table145[[#This Row],[50% IFR - AE]],-15), " ") | Q34: 4/25/2024-Complete
A35: FTY02 | B35: GEORGIA | C35: Morrison Hershfield | D35: Bid | E35: Lee Percy | F35: LPercy@morrisonhershfield.com | J35: =IFERROR(WORKDAY(Table145[[#This Row],[50% IFR - AE]],-15), " ") -> 45139 | K35: 8/15/2023-Complete | L35: 45160 | M35: 9/8/2023 - complete | N35: 9/12/2023 - complete | O35: 10/10/2023 - Complete | P35: 10/12/2023- Complete | X35: Need to update the BOM to comba unit.
A36: FTY03 | J36: =IFERROR(WORKDAY(Table145[[#This Row],[50% IFR - AE]],-15), " ") | L36: 5/9/2024-Complete | N36: 45446 | P36: 45474
A37: IAD05 | J37: =IFERROR(WORKDAY(Table145[[#This Row],[50% IFR - AE]],-15), " ") | Q37: TBD
A38: IAD12 | B38: LEESBURG, VA | C38: Syska | D38: Design | E38: Liam Wall | F38: lwall@syska.com | H38: A | J38: =IFERROR(WORKDAY(Table145[[#This Row],[50% IFR - AE]],-15), " ") | K38: Complete | L38: 2/22/2023 - Complete | N38: 3/29/2023 - Complete | P38: 45042 | Q38: 45076
A39: IAD13 | B39: LEESBURG, VA | C39: Syska | D39: Design | E39: Liam Wall | F39: lwall@syska.com | H39: A | J39: =IFERROR(WORKDAY(Table145[[#This Row],[50% IFR - AE]],-15), " ") | K39: Complete | L39: Complete | M39: Complete | N39: 2/9/2023 - Complete | O39: Complete | P39: 3/24/2023 - Complete | Q39: 45050 | X39: Riser Info - no IFR yet
A40: IAD14 | B40: LEESBURG, VA | D40: Bid | E40: TBD | H40: A | J40: =IFERROR(WORKDAY(Table145[[#This Row],[50% IFR - AE]],-15), " ")
...

Sheet Design-formattingv1
A1: NAME | B1: LOCATION | C1: A/E | D1: Phase (Design or CA) | E1: AE-PM Name | F1: AE-PM Contact | G1: S2 PM | H1: Project Status | I1: Floorplans Received | J1: Floor Plans Needed | K1: 50% IFR - Notora | L1: 50% IFR - AE | M1: 100% IFR - Notora | N1: 100% IFR - AE | O1: IFP - Notora | P1: IFP - AE | Q1: IFC | R1: Project Start | S1: Submittal | T1: Substantial Completion | U1: Issue For Record | V1: Completion | W1: Commissioning | X1: Action Item Needed | Y1: Comments
A2: ATL06 | B2: Atlanta | C2: Highland Associates | D2: Design | E2: Christopher Ritchie | F2: critchie@ha-ny.com | H2: A | I2: Supposed to be 4/7/2023 | J2: =IFERROR(WORKDAY(Table14[[#This Row],[50% IFR - AE]],-15), " ") | K2: Complete | M2: No Notora | N2: 10/3/2023- Complete | O2: No Notora | P2: 10/24/2023-Complete | Q2: 2/12/2024-complete | X2: Need to track down: Floor Plans, AHJ (Authorities having jurisdiction contact), enforced code | Y2: Location: East Point GA Lat Long: 33*38'30"N, 84*30'59"W FloorPlans to be updated Friday the 7th
A3: ATL07 | H3: A | J3: 5/13/2024-complete | K3: 45435 | L3: 45436 | N3: 45468
A4: AVC02 | H4: A | J4: =IFERROR(WORKDAY(Table14[[#This Row],[50% IFR - AE]],-15), " ") | L4: 3/25/2024-Complete | N4: 4/29/2024-complete | P4: 45427 | V4: Need as-builts/testing for AVC01. Some weirdness w AVC01 | X4: DAS and Public safety Proposal needed.
A5: AVC17 | B5: SOUTH HILL, VA | C5: Highland Associates | D5: Design | E5: Hector Hernandez | F5: hhernandez@ha-ny.com | G5: Bram Wathen | H5: A | I5: 44981 | J5: =IFERROR(WORKDAY(Table14[[#This Row],[50% IFR - AE]],-15), " ") | K5: 3/8/2023 - complete | L5: 3/20/2023- complete | M5: 4/17/2023 - complete | N5: 4/24/2023 - complete | O5: 6/2/2023 - complete | P5: 6/5/2023 - complete | Q5: 8/3/2023-Complete | X5: Update the IFC Date | Y5: 3 Different Issues. Need to confrim if power supply for fiber optical master is required. Need ROIP specs, Site Heat map.
A6: AVC18 | B6: SOUTH HILL, VA | C6: Highland Associates | D6: Design | E6: Hector Hernandez | F6: hhernandez@ha-ny.com | G6: Bram Wathen | H6: A | I6: 44988 | J6: =IFERROR(WORKDAY(Table14[[#This Row],[50% IFR - AE]],-15), " ") | K6: 3/15/2023 - complete | L6: 3/20/2023 - complete | M6: 4/17/2023 - complete | N6: 4/24/2023 - complete | O6: 6/2/2023 - complete | P6: 6/5/2023 - complete | Q6: 8/3/2023-Complete | X6: Update the IFC Date | Y6: Review Drawings prior to IFP
A7: AVC43 | B7: SOUTH HILL, VA | C7: Swanson Rink | D7: Design | E7: Ryan Sims | F7: RSims@swansonrink.com | H7: C | I7: 44874 | J7: =IFERROR(WORKDAY(Table14[[#This Row],[50% IFR - AE]],-15), " ") | K7: Complete | L7: 11/21/2022 - Complete | M7: Complete | P7: Complete | X7: 2x2 cabinet
A8: CCO07 | H8: A | J8: =IFERROR(WORKDAY(Table14[[#This Row],[50% IFR - AE]],-15), " ") | K8: 8/23/2023 - complete | L8: 9/7/2023 - complete | M8: No Notora | N8: 10/19/2023-Complete | O8: No Notora | P8: 11/7/2023-Complete
A9: CHI05 | B9: Chicago | I9: 45065 | J9: =IFERROR(WORKDAY(Table14[[#This Row],[50% IFR - AE]],-15), " ") | K9: 5/26/2023 - complete | Q9: 45384 | U9: No Notora | Y9: We need NT proposal
A10: CHI11 | B10: Chicago | I10: X | J10: =IFERROR(WORKDAY(Table14[[#This Row],[50% IFR - AE]],-15), " ") | K10: 5/26/2023 - complete | P10: 3/11/2024-Complete | Y10: We need NT proposal
A11: CHI22 | B11: Chicago | H11: A | J11: =IFERROR(WORKDAY(Table14[[#This Row],[50% IFR - AE]],-15), " ") | P11: 1/11/2024-COMPLETE | Q11: 1/19/2024-complete | Y11: IFP DRB17 Print
A12: CLT04 | B12: North Carolina | C12: Olson | D12: Design | E12: David Barber | F12: dbarber@olsson.com | G12: Bram Wathen | H12: A | I12: 44957 | J12: =IFERROR(WORKDAY(Table14[[#This Row],[50% IFR - AE]],-15), " ") | K12: 2/16/2023 - complete | L12: 2/16/2023 - complete | M12: 4/12/2023 -complete | N12: 4/26/2023 - complete | O12: 2/20/2024-Complete | P12: 2/21/2024-Complete | X12: Title block updates. Request sent to Stephen 5/11 | Y12: Get address and find cell towers
A13: CLT10 | B13: North Carolina | C13: Olsson | D13: Design | E13: Meg Plank | F13: mplank@olsson.com | H13: A | I13: X | J13: =IFERROR(WORKDAY(Table14[[#This Row],[50% IFR - AE]],-15), " ") | K13: 6/30/2023 - Complete | L13: 7/06/2023 - Complete | M13: 8/25/2023 - complete | N13: 8/31/2023-Complete | O13: 2/20/2024-Complete | P13: 2/21/2024-Complete | X13: Site Plans & Floor Plans | Y13: Project Kick off June 1st.
A14: CLT11 | C14: Olson | D14: Design | E14: David Barber | F14: dbarber@olsson.com | G14: Bram Wathen | H14: P | J14: =IFERROR(WORKDAY(Table14[[#This Row],[50% IFR - AE]],-15), " ")
A15: CLT17 | C15: Olson | D15: Design | E15: David Barber | F15: dbarber@olsson.com | G15: Bram Wathen | H15: P | I15: X | J15: =IFERROR(WORKDAY(Table14[[#This Row],[50% IFR - AE]],-15), " ") | K15: 45240 | L15: 11/16/2023-complete | M15: 45280 | N15: 1/3/2024-Complete | P15: 2/14/2024-Complete | Y15: Not doing the CADs for this one
A16: CPQ03 | B16: BRAZIL | C16: Deerns | D16: Design | E16: Gabriel Pereira | F16: gabriel.pereira@deerns.com | H16: C | J16: =IFERROR(WORKDAY(Table14[[#This Row],[50% IFR - AE]],-15), " ") | Q16: 45215
A17: CPQ07 | B17: BRAZIL | C17: Deerns | D17: Design | E17: Gabriel Pereira | F17: gabriel.pereira@deerns.com | H17: C | I17: X | J17: =IFERROR(WORKDAY(Table14[[#This Row],[50% IFR - AE]],-15), " ") | K17: 2/17/2023 - complete | L17: 1/11/2023 - Complete | X17: Need updated IFR Date, if we're doing the CAD's | Y17: 1/25: emailed Kelwin asking for info
A18: CPQ08 | J18: =IFERROR(WORKDAY(Table14[[#This Row],[50% IFR - AE]],-15), " ") | L18: 1/8/2024-Complete
A19: CPQ11 | B19: BRAZIL | C19: Deerns | D19: Design | E19: Gabriel Pereira | F19: gabriel.pereira@deerns.com | H19: C | I19: X | J19: =IFERROR(WORKDAY(Table14[[#This Row],[50% IFR - AE]],-15), " ") | K19: Complete
A20: CYS17 | B20: Cheyanne | C20: Jacobs | D20: Design | E20: Kristin McCue | F20: Kristin.McCue@jacobs.com | H20: C | J20: =IFERROR(WORKDAY(Table14[[#This Row],[50% IFR - AE]],-15), " ") | M20: Complete | N20: 1/24/2023-complete | O20: complete | P20: complete | X20: IFP from WT | Y20: 2/6/2023: WT indicates a 2/13 delivery date. 2/6/2023: emailed WT requesting IFP update 1/24: recieved updated design fromWT, uploaded 1/20: recieved design from David. Emailed AE the drawing list and uploaded files to AE and S2 1/19: This is a 'WT' site, emailed Davide requesting design update 1/18: sent philip design pkg 4 email 1/13/23: emailed Kristen requesting update
A21: DFW20 | J21: =IFERROR(WORKDAY(Table14[[#This Row],[50% IFR - AE]],-15), " ") | Q21: 3/8/2024-complete
A22: DSM12 | B22: DES MOINES | C22: Burns & McDonnell | D22: Design | E22: Kylie Hornbeck | F22: khornbeck@burnsmcd.com | H22: C | J22: =IFERROR(WORKDAY(Table14[[#This Row],[50% IFR - AE]],-15), " ") | X22: Nick coordinating with AE
A23: DSM14 | B23: DES MOINES | C23: Burns & McDonnell | D23: Design | E23: Kylie Hornbeck | F23: khornbeck@burnsmcd.com | H23: C | J23: =IFERROR(WORKDAY(Table14[[#This Row],[50% IFR - AE]],-15), " ") | X23: Nick coordinating with AE
A24: DSM15 | B24: DES MOINES | C24: Burns & McDonnell | D24: Design | E24: Kylie Hornbeck | F24: khornbeck@burnsmcd.com | H24: C | J24: =IFERROR(WORKDAY(Table14[[#This Row],[50% IFR - AE]],-15), " ") | X24: Need Floorplans & Schedule - Nick to follow up with AE
A25: DSM40 | B25: DES MOINES | C25: Burns & McDonnell | D25: Design | E25: Kylie Hornbeck | F25: khornbeck@burnsmcd.com | H25: C | J25: =IFERROR(WORKDAY(Table14[[#This Row],[50% IFR - AE]],-15), " ") | Q25: 5/8/2024-Complete | X25: Nick coordinating with AE
A26: DSM41 | B26: DES MOINES | C26: Burns & McDonnell | D26: Design | E26: Kylie Hornbeck | F26: khornbeck@burnsmcd.com | H26: C | J26: =IFERROR(WORKDAY(Table14[[#This Row],[50% IFR - AE]],-15), " ") | X26: Nick coordinating with AE
A27: EAT04 | B27: WEANATCHEE, WA | C27: ESD | D27: Design | E27: Chad Mendell | F27: cmendell@esdglobal.com | H27: C | J27: =IFERROR(WORKDAY(Table14[[#This Row],[50% IFR - AE]],-15), " ") | K27: Complete | L27: 12/1/2022 - Complete | M27: Complete | N27: 1/12/2023 - Complete | O27: 1/19/23-complete | P27: 1/26/2023-complete | Q27: 5/31/2023-Complete | Y27: 2/6/23: IFC is TBD no update1/25: recieved updated design from Philip, uploaded to AE and S2 1/19: recieved updated design from Philip, uploaded to BIM and S2 1/19: uploaded specs, requested IFP design from Philip 1/18: sent IFP instructions to Notora
A28: EAT05 | B28: WEANATCHEE, WA | C28: ESD | D28: Bid | E28: Chad Mendell | F28: cmendell@esdglobal.com | H28: A | I28: 45033 | J28: =IFERROR(WORKDAY(Table14[[#This Row],[50% IFR - AE]],-15), " ") | K28: 5/3/2023 - complete | L28: 4/20/2023 - complete | M28: 5/19/2023 - complete | N28: 5/25/2023 - complete | O28: complete | P28: 6/13/2023 - complete | Q28: 3/5/2024-Complete | X28: Notora Internal review return 5/1-5/2 | Y28: May
A29: EAT06 | H29: A | J29: =IFERROR(WORKDAY(Table14[[#This Row],[50% IFR - AE]],-15), " ") | K29: 8/9/2023--Complete | L29: 8/1/2023-Complete | N29: 9/7/2023 - complete | P29: 9/26/2023-Complete
A30: EAT09 | H30: A | I30: 8/16/2023? | J30: =IFERROR(WORKDAY(Table14[[#This Row],[50% IFR - AE]],-15), " ") | N30: 9/7/2023 - complete | P30: 9/26/2023-Complete
A31: EAT12 | B31: WEANATCHEE, WA | C31: ESD | D31: Design | E31: Chad Mendell | F31: cmendell@esdglobal.com | H31: A | J31: =IFERROR(WORKDAY(Table14[[#This Row],[50% IFR - AE]],-15), " ") | K31: 2/20/2023-complete | L31: 2/23/2023-complete | M31: 3/20/2023 - complete | N31: 3/9/2023 - complete | O31: complete | P31: 4/6/2023 - complete | Q31: 3/21/2024 Complete | X31: Change notes in the Public Safety. Cover the L1 containment unless AHJ approves alternate means and methods. Pull box detail | Y31: 2/15: in internal review 2/15: requested update from Notora 2/3/23: floor plan delivered to Notora 2/1: Harold got floorplans today; 1/18: Design is resuming with meeting 1/30
A32: EAT13 | B32: WEANATCHEE, WA | C32: ESD | D32: Design | E32: Chad Mendell | F32: cmendell@esdglobal.com | H32: A | I32: X | J32: =IFERROR(WORKDAY(Table14[[#This Row],[50% IFR - AE]],-15), " ") | K32: 6/14/2023 - complete | L32: 6/15/2023 - complete | M32: 7/18/2023-Complete | N32: 7/20/2023-Complete | O32: 8/1/2023-Complete | P32: 8/2/2023-Complete | Q32: 4/9/2024-complete | Y32: Starting the week of 5/8
A33: EAT14 | B33: WEANATCHEE, WA | H33: A | I33: X | J33: =IFERROR(WORKDAY(Table14[[#This Row],[50% IFR - AE]],-15), " ") | K33: 9/27/2023 - complete | L33: 9/21/2023 - Complete | M33: 10/27/2023-complete | N33: 11/28/2023-Complete | P33: 12/14/2023 - Complete | Q33: 45427 | X33: Battery backups, near far, L1 containement?
A34: FTY01 | J34: =IFERROR(WORKDAY(Table14[[#This Row],[50% IFR - AE]],-15), " ") | Q34: 4/25/2024-Complete
A35: FTY02 | B35: GEORGIA | C35: Morrison Hershfield | D35: Bid | E35: Lee Percy | F35: LPercy@morrisonhershfield.com | J35: =IFERROR(WORKDAY(Table14[[#This Row],[50% IFR - AE]],-15), " ") -> 45139 | K35: 8/15/2023-Complete | L35: 45160 | M35: 9/8/2023 - complete | N35: 9/12/2023 - complete | O35: 10/10/2023 - Complete | P35: 10/12/2023- Complete | X35: Need to update the BOM to comba unit.
A36: FTY03 | J36: =IFERROR(WORKDAY(Table14[[#This Row],[50% IFR - AE]],-15), " ") | L36: 5/9/2024-Complete | N36: 45446 | P36: 45474
A37: IAD05 | J37: =IFERROR(WORKDAY(Table14[[#This Row],[50% IFR - AE]],-15), " ") | Q37: TBD
A38: IAD12 | B38: LEESBURG, VA | C38: Syska | D38: Design | E38: Liam Wall | F38: lwall@syska.com | H38: A | J38: =IFERROR(WORKDAY(Table14[[#This Row],[50% IFR - AE]],-15), " ") | K38: Complete | L38: 2/22/2023 - Complete | N38: 3/29/2023 - Complete | P38: 45042 | Q38: 45076
A39: IAD13 | B39: LEESBURG, VA | C39: Syska | D39: Design | E39: Liam Wall | F39: lwall@syska.com | H39: A | J39: =IFERROR(WORKDAY(Table14[[#This Row],[50% IFR - AE]],-15), " ") | K39: Complete | L39: Complete | M39: Complete | N39: 2/9/2023 - Complete | O39: Complete | P39: 3/24/2023 - Complete | Q39: 45050 | X39: Riser Info - no IFR yet
A40: IAD14 | B40: LEESBURG, VA | D40: Bid | E40: TBD | H40: A | J40: =IFERROR(WORKDAY(Table14[[#This Row],[50% IFR - AE]],-15), " ")
...

Sheet Design
A1: NAME | B1: LOCATION | C1: A/E | D1: Phase (Design or CA) | E1: AE-PM Name | F1: AE-PM Contact | G1: S2 PM | H1: Project Status | I1: Floorplans Received | J1: Floor Plans Needed | K1: 50% IFR - Notora | L1: 50% IFR - AE | M1: 100% IFR - Notora | N1: 100% IFR - AE | O1: IFP - Notora | P1: IFP - AE | Q1: IFC | R1: Project Start | S1: Submittal | T1: Substantial Completion | U1: Issue For Record | V1: Completion | W1: Commissioning | X1: Action Item Needed | Y1: Comments
A2: ATL06 | B2: Atlanta | C2: Highland Associates | D2: Design | E2: Christopher Ritchie | F2: critchie@ha-ny.com | H2: C | I2: Supposed to be 4/7/2023 | J2: =IFERROR(WORKDAY(Table1[[#This Row],[50% IFR - AE]],-15), " ") | K2: Complete | M2: No Notora | N2: 10/3/2023- Complete | O2: No Notora | P2: 10/24/2023-Complete | Q2: 2/12/2024-complete | X2: Need to track down: Floor Plans, AHJ (Authorities having jurisdiction contact), enforced code | Y2: Location: East Point GA Lat Long: 33*38'30"N, 84*30'59"W FloorPlans to be updated Friday the 7th
A3: ATL07 | H3: C | J3: 5/13/2024-complete | K3: 5/23/2024-complete | L3: 5/24/2024-complete | Y3: Work completed, assigned to another contractor
A4: AVC01-DRB13 | B4: SOUTH HILL, VA | H4: C | J4: no | M4: 1/3/2025-complete | N4: 4/24/2025-Complete | P4: 1/24/2025-complete | Q4: 1/28/2025-complete
A5: AVC02 | B5: SOUTH HILL, VA | H5: C | J5: =IFERROR(WORKDAY(Table1[[#This Row],[50% IFR - AE]],-15), " ") | L5: 3/25/2024-Complete | N5: 4/29/2024-complete | P5: 5/15/2024-complete | Q5: No S2A - DayWireless | V5: Need as-builts/testing for AVC01. Some weirdness w AVC01 | X5: DAS and Public safety Proposal needed. | Y5: Given to DWS. Highland associates
A6: AVC09-DRB10 | B6: SOUTH HILL, VA | H6: C | J6: no | M6: 12/31/2024-Complete | N6: 4/25/2025- Complete | P6: 1/24/2025-complete | Q6: 1/28/2025-complete
A7: AVC11 | B7: SOUTH HILL, VA | C7: Highland Associates | D7: Design | E7: Paul Duffy (Bim Manager) | F7: pduffy@ha-ny.com | H7: C | J7: 6/26/24-complete | L7: 7/16/2024-Complete | N7: 8/21/2024-Complete | P7: 9/10/2024-complete | Q7: 1/16/2025-completed | X7: Add note to drawings: Carrier coordination must occur at the beginning of the project. As soon as they are awarded contract. | Y7: 8/29: Bram emailed NT: next AVC11 Issuance (IFP) we will need to add a few items. See email thread.
A8: AVC17 | B8: SOUTH HILL, VA | C8: Highland Associates | D8: Design | E8: Hector Hernandez | F8: hhernandez@ha-ny.com | G8: Bram Wathen | H8: C | I8: 2/24/2023 - complete | J8: =IFERROR(WORKDAY(Table1[[#This Row],[50% IFR - AE]],-15), " ") | K8: 3/8/2023 - complete | L8: 3/20/2023- complete | M8: 4/17/2023 - complete | N8: 4/24/2023 - complete | O8: 6/2/2023 - complete | P8: 6/5/2023 - complete | Q8: 8/3/2023-Complete | X8: Update the IFC Date | Y8: 3 Different Issues. Need to confrim if power supply for fiber optical master is required. Need ROIP specs, Site Heat map.
A9: AVC18 | B9: SOUTH HILL, VA | C9: Highland Associates | D9: Design | E9: Hector Hernandez | F9: hhernandez@ha-ny.com | G9: Bram Wathen | H9: C | I9: 3/3/2023 - complete | J9: =IFERROR(WORKDAY(Table1[[#This Row],[50% IFR - AE]],-15), " ") | K9: 3/15/2023 - complete | L9: 3/20/2023 - complete | M9: 4/17/2023 - complete | N9: 4/24/2023 - complete | O9: 6/2/2023 - complete | P9: 6/5/2023 - complete | Q9: 8/3/2023-Complete | X9: Update the IFC Date | Y9: Review Drawings prior to IFP
A10: AVC17/18-DRB | B10: SOUTH HILL, VA | C10: Highland Associates | D10: Design | E10: Hector Hernandez | F10: hhernandez@ha-ny.com | G10: Bram Wathen | H10: A | J10: =IFERROR(WORKDAY(Table1[[#This Row],[50% IFR - AE]],-15), " ") | K10: 11/25/2024-complete | L10: 12/3/2024-complete | N10: 4/17/2025-complete | O10: 12/13/2024-complete | Q10: 12/18/2024-Complete | X10: 5/6: Waiting on Commscope for ROM. Proposal received from Andrews 4/30 Waiting on OneCell BOM pricing - Wesco Note-need benchmark | Y10: 5/6: Waiting on Commscope for ROM. Proposal received from Andrews 4/30 Waiting on OneCell BOM pricing - Wesco Note-need benchmark
A11: AVC19 | B11: SOUTH HILL, VA | C11: Highland Associates | D11: Design | E11: Hector Hernandez | F11: hhernandez@ha-ny.com | G11: Bram Wathen | H11: C | J11: 12/16/24-complete | K11: 1/13/2025-complete | L11: 1/22/2025-complete | M11: 3/11/2025-cancelled | N11: 3/12/2025-cancelled | P11: 3/25/2024-cancelled
A12: AVC20 | B12: SOUTH HILL, VA | C12: Highland Associates | D12: Design | E12: Hector Hernandez | F12: hhernandez@ha-ny.com | G12: Bram Wathen | H12: C | J12: 2/26/25-complete | K12: 3/10/2025-cancelled | L12: 3/12/2025-cancelled
A13: AVC21 | B13: SOUTH HILL, VA | C13: Highland Associates | D13: Design | E13: Hector Hernandez | F13: hhernandez@ha-ny.com | G13: Bram Wathen | H13: C | J13: cancelled | K13: 4/21/2025-cancelled | L13: 4/24/2025-cancelled
A14: AVC43 | B14: SOUTH HILL, VA | C14: Swanson Rink | D14: Design | E14: Ryan Sims | F14: RSims@swansonrink.com | H14: C | I14: 44874 | J14: =IFERROR(WORKDAY(Table1[[#This Row],[50% IFR - AE]],-15), " ") | K14: Complete | L14: 11/21/2022 - Complete | M14: Complete | P14: Complete | X14: 2x2 cabinet
A15: AVC43_DRB07 | B15: SOUTH HILL, VA | C15: Swanson Rink | D15: Design | E15: Ryan Sims | F15: RSims@swansonrink.com | H15: C | J15: no | M15: 12/31/2024-complete | N15: 4/25/2025-Complete | P15: 1/24/2025-complete | Q15: 1/27/2025-complete
A16: BN_Campus | B16: BOYDTON,VA | H16: C | J16: =IFERROR(WORKDAY(Table1[[#This Row],[50% IFR - AE]],-15), " ") | O16: 4/28/2025-complete | P16: 4/4/2025-complete | X16: BW – schedule meeting for Thursday 5/7 KP invoice after delivered.
A17: BN7-8Rev | B17: BOYDTON,VA | H17: C | J17: =IFERROR(WORKDAY(Table1[[#This Row],[50% IFR - AE]],-15), " ") | O17: 5/1/2025-complete | X17: BW – schedule meeting for Thursday 5/7 KP invoice after delivered.
A18: CCO06DRB13 | H18: C | J18: =IFERROR(WORKDAY(Table1[[#This Row],[50% IFR - AE]],-15), " ") | M18: 5/1/2025-completed | N18: 5/6/2025-Completed | Q18: 5/8/2025-complete
A19: CCO07 | B19: PALMETTO, GA | H19: C | J19: =IFERROR(WORKDAY(Table1[[#This Row],[50% IFR - AE]],-15), " ") | K19: 8/23/2023 - complete | L19: 9/7/2023 - complete | M19: No Notora | N19: 10/19/2023-Complete | O19: No Notora | P19: 11/7/2023-Complete
A20: CCO07DCN07 | B20: PALMETTO, GA | F20: Steve.Baum@jacob.com | H20: C | J20: =IFERROR(WORKDAY(Table1[[#This Row],[50% IFR - AE]],-15), " ") | O20: 5/23/2025-complete | P20: 5/23/2025-Complete | Q20: 6/6/25-complete
A21: CCO08 | B21: PALMETTO, GA | C21: Jacobs | D21: Design | E21: Michael Mcloone | F21: Michael.Mcloone@jacobs.com | H21: C | I21: 7/10/2024-Complete | J21: 7/10/2024-Complete | K21: 7/19/2024-Complete | L21: 7/29/2024-Complete | M21: 8/23/24-complete | N21: 9/3/2024-Complete | O21: 9/16/2024-complete | P21: 9/18/2024-complete | Q21: TBD | V21: Launch(Admin&Colo1) & PKG3-6 Fitout. Separate packages | X21: 8/8/24: NT requests 50%s by 8/13 in order to make the 8/22 date for 100%'s. 8/6/24 HS – agree on a standard PSDAS approach – 4 or 3 antennas per COLO, 1 or 2 FBDAs per DC - no opinion from S2A side other than we want a uniform approach across all our projects. Verify Centerline calculated, not guessed at, the potential of near far. One option to calculate: Steps to Calculate Determine the Power Levels: Measure the power levels of the signals from both the near and far transmitters (radios). Calculate Path Loss: Use the path loss formula to determine how much the signal strength decreases over distance. The path loss ( L ) can be calculated using: L=10⋅n⋅log10​(d)+C where ( n ) is the path loss exponent, ( d ) is the distance, and ( C ) is a constant. Evaluate Interference: Assess the interference caused by the stronger signal on the weaker one. This can be done using the Signal-to-Interference Ratio (SIR): SIR= ​Pfar​​/ Pnear , where ( P_{\text{far}} ) is the power of the far signal and ( P_{\text{near}} ) is the power of the near signal.
A22: CCO08DCN | B22: PALMETTO, GA | H22: A | J22: =IFERROR(WORKDAY(Table1[[#This Row],[50% IFR - AE]],-15), " ") | K22: 5/12/2025-complete | O22: 7/17/25-complete | P22: 8/5/2025-complete | X22: 7/28: IFP due date changed to 8/5 per email from BW. 7/21: Draft IFP delivered to A/E, final due 8/11.
A23: CHI05 | B23: Chicago | H23: C | I23: 5/19/2023 - complete | J23: =IFERROR(WORKDAY(Table1[[#This Row],[50% IFR - AE]],-15), " ") | K23: 5/26/2023 - complete | Q23: 4/2/2024-complete | U23: No Notora | Y23: We need NT proposal
A24: CHI11 | B24: Chicago | H24: C | I24: X | J24: =IFERROR(WORKDAY(Table1[[#This Row],[50% IFR - AE]],-15), " ") | K24: 5/26/2023 - complete | P24: 3/11/2024-Complete | Y24: We need NT proposal
A25: CHI22 | B25: Chicago | H25: C | J25: =IFERROR(WORKDAY(Table1[[#This Row],[50% IFR - AE]],-15), " ") | P25: 1/11/2024-COMPLETE | Q25: 1/19/2024-complete | Y25: IFP DRB17 Print
A26: CLT04 | B26: North Carolina | C26: Olson | D26: Design | E26: David Barber | F26: dbarber@olsson.com | G26: Bram Wathen | H26: C | I26: 1/31/2023 - complete | J26: =IFERROR(WORKDAY(Table1[[#This Row],[50% IFR - AE]],-15), " ") | K26: 2/16/2023 - complete | L26: 2/16/2023 - complete | M26: 4/12/2023 -complete | N26: 4/26/2023 - complete | O26: 2/20/2024-Complete | P26: 2/21/2024-Complete | Q26: 1/3/2025-complete | X26: Title block updates. Request sent to Stephen 5/11 | Y26: Get address and find cell towers
A27: CLT05 | B27: North Carolina | H27: C | J27: 1/8/25-complete | K27: 1/17/2025-completed | L27: 1/21/2025-Complete | M27: 2/10/2025-complete | N27: 2/13/2025-Complete | Y27: 9/17/24: Unclear if S2A got contract or not.
A28: CLT10 | B28: North Carolina | C28: Olsson | D28: Design | E28: Meg Plank | F28: mplank@olsson.com | H28: C | I28: X | J28: =IFERROR(WORKDAY(Table1[[#This Row],[50% IFR - AE]],-15), " ") | K28: 6/30/2023 - Complete | L28: 7/06/2023 - Complete | M28: 8/25/2023 - complete | N28: 8/31/2023-Complete | O28: 2/20/2024-Complete | P28: 2/21/2024-Complete | Q28: 1/3/2025-complete | X28: Site Plans & Floor Plans | Y28: Project Kick off June 1st.
A29: CLT11 | B29: North Carolina | H29: C | J29: 1/23/25-complete | K29: 2/3/2025-complete | L29: 2/4/2025-Complete | M29: 3/14/2025-cancelled | N29: 3/18/2025-cancelled | P29: 4/8/2025-cancelled
A30: CLT17 | B30: North Carolina | C30: Olson | D30: Design | E30: David Barber | F30: dbarber@olsson.com | G30: Bram Wathen | H30: C | I30: X | J30: =IFERROR(WORKDAY(Table1[[#This Row],[50% IFR - AE]],-15), " ") | K30: 11/10/2023 - complete | L30: 11/16/2023-complete | M30: 12/20/2023 - complete | N30: 1/3/2024-Complete | P30: 2/14/2024-Complete | Q30: 1/3/2025-complete | Y30: Not doing the CADs for this one
A31: CLT18 | B31: North Carolina | H31: C | J31: 2/17/25-completed | K31: 2/25/2025-completed | L31: 2/27/2025-complete | M31: 4/11/2025-cancelled | N31: 4/15/2025-cancelled | P31: 5/6/2025-cancelled
A32: CPQ03 | B32: BRAZIL | C32: Deerns | D32: Design | E32: Gabriel Pereira | F32: gabriel.pereira@deerns.com | H32: C | J32: =IFERROR(WORKDAY(Table1[[#This Row],[50% IFR - AE]],-15), " ") | Q32: 10/16/2023-complete
A33: CPQ04 | B33: BRAZIL | H33: C | J33: 9/13/2024-complete | K33: 9/19/24-complete | L33: 9/24/2024-complete | M33: 10/7/2024-complete | N33: 10/14/2024-complete | Y33: 8/29/24: added to list. project coming up.
A34: CPQ07 | B34: BRAZIL | C34: Deerns | D34: Design | E34: Gabriel Pereira | F34: gabriel.pereira@deerns.com | H34: C | I34: X | J34: =IFERROR(WORKDAY(Table1[[#This Row],[50% IFR - AE]],-15), " ") | K34: 2/17/2023 - complete | L34: 1/11/2023 - Complete | X34: Need updated IFR Date, if we're doing the CAD's | Y34: 1/25: emailed Kelwin asking for info
A35: CPQ08 | B35: BRAZIL | H35: C | J35: =IFERROR(WORKDAY(Table1[[#This Row],[50% IFR - AE]],-15), " ") | L35: 1/8/2024-Complete
A36: CPQ11 | B36: BRAZIL | C36: Deerns | D36: Design | E36: Gabriel Pereira | F36: gabriel.pereira@deerns.com | H36: C | I36: X | J36: =IFERROR(WORKDAY(Table1[[#This Row],[50% IFR - AE]],-15), " ") | K36: Complete
A37: CYS13 | B37: Cheyanne | H37: C | J37: =IFERROR(WORKDAY(Table1[[#This Row],[50% IFR - AE]],-15), " ") | U37: 9/10/2024-completed | X37: 7/29/24: Bram follow up with Kristin McCue for details/confirmed schedule | Y37: 7/17/24: CYS13 Record Drawings (Admin and COLOs 1 through 5) to close out the project. The latest federated model is available in Navisworks and all disciplines should have final approved redlines (with the exception of Mechanical, where we are tracking down some last info). Please begin working on Record Drawings with the idea to submit as early as possible in August (date TBC once we receive final Mech info). The client has asked us to submit these as soon as possible, so we’re being asked to advance what we can.
A38: CYS17 | B38: Cheyanne | C38: Jacobs | D38: Design | E38: Kristin McCue | F38: Kristin.McCue@jacobs.com | H38: A | J38: =IFERROR(WORKDAY(Table1[[#This Row],[50% IFR - AE]],-15), " ") | M38: Complete | N38: 1/24/2023-complete | O38: complete | P38: complete | U38: 7/11/2025-complete | X38: 6/10/25: Redlines expected end of June(?) | Y38: 2/6/2023: WT indicates a 2/13 delivery date. 2/6/2023: emailed WT requesting IFP update 1/24: recieved updated design fromWT, uploaded 1/20: recieved design from David. Emailed AE the drawing list and uploaded files to AE and S2 1/19: This is a 'WT' site, emailed Davide requesting design update 1/18: sent philip design pkg 4 email 1/13/23: emailed Kristen requesting update
A39: DFW20 | B39: Irving, TX | H39: C | J39: =IFERROR(WORKDAY(Table1[[#This Row],[50% IFR - AE]],-15), " ") | Q39: 3/8/2024-complete
A40: DSM12 | B40: DES MOINES | C40: Burns & McDonnell | D40: Design | E40: Kylie Hornbeck | F40: khornbeck@burnsmcd.com | H40: C | J40: =IFERROR(WORKDAY(Table1[[#This Row],[50% IFR - AE]],-15), " ") | X40: Nick coordinating with AE
...

Sheet Site Visit Schedule
A1: Site | B1: Status | C1: S2 Advisors | D1: Date | E1: Test Data Received/Location | F1: Confirmed/Not Confirmed | G1: Notes
A2: ATL06 | B2: Complete | C2: Bram | D2: 45986 | F2: Confirmed
A3: CC006 | B3: Complete | C3: Bram | D3: 45986 | F3: Confirmed
A4: CHI05 | B4: Complete | C4: Harold | D4: Late April | E4: After March 20th | F4: Not Confirmed | G4: 4/13: Katie asked Harold for specific dates 3/17: See the upcoming timeline for CHI05 DAS Commissioning: - March 10th & 11th – Day Wireless will be onsite to repair the current DAS antenna run and fix any open issues with the systems functionality - March 12th & 13th – Day Wireless will be onsite to complete the commissioning of COLO 2-5 DAS system - March 20th – Walsh plans to have all DAS testing and documentation sent into the AE for review and approval CHI05 is turned over and actively operating under MSFT Ops. Following the submission of test reports, your team can review and you are more than welcome to come to site for a final walk (most likely week of March 30th, from our discussion).3/6: Walsh DAS contractor says DAS repairs are happening on the 10th, then CX-ing a couple days after. They expect to get test data to S2A by the 20th. 2/18: We have not heard anything further from the CHI05 Contractor beyond the attached. We understand S2A’s recommendation to hold off on DAS/PS/RoIP Record Drawings at this time. 1/16: AK said there is a Verizon issue. HS asked for submittals and a site visit. 1/5: Waiting to hear back from Andrew Kreb. Back in office today. CHI05 campus turned over on 12/16
A5: YTO11 | B5: Completed | C5: Harold | D5: 46002 | F5: Confirmed | G5: Same visit: CHI05, YTO11 - 8am (7:30am safety meeting) if possible, the preference is to have you take the site safety training which happens at 7:30AM, this will allow you permanent site access and also allow you access to YTO40 in the future, site safety training is approximately 1 hour long. fill out the QR code per the second email when convenient.
A6: YQB04 | B6: Completed | C6: Harold | D6: 46006 | F6: Confirmed | G6: Meet at the site at 8am
A7: AVC43 | B7: Completed | C7: Bram | D7: 46008 | F7: Confirmed | G7: Same visit: IAD05, MNZ03, AVC43
A8: IAD05 | B8: Completed | C8: Bram | D8: 12/15-12/19 | F8: Confirmed | G8: Same visit: IAD05, MNZ03, AVC43
A9: MNZ03 | B9: Completed | C9: Bram | D9: 12/15-12/19 | F9: Confirmed | G9: Same visit: IAD05, MNZ03, AVC43
A10: EAT04 | B10: On Hold | C10: Harold | D10: Week of March 2-6? | F10: Not Confirmed | G10: 2/18: I don’t believe we have been awarded the EAT04 install yet, so this hasn’t been schedule. I’ve forwarded your email on to our account manage who will have better visibility into current status.1/5: No RFIs or submittals. Site not ready, BW to chat with Michael about EAT04 and 12.
A11: EAT12 | B11: Completed | C11: Harold | D11: Week of March 2-6? | F11: Not Confirmed | G11: 2/20: PSDAS Cx in progress - ETA finish: 3/2-3/6 Cell DAS Cx in progress - ETA finish: 3/2-3/6 2/18: Katie reached out to Grant Potter about status of the passive layer testing. punch walk COLO 3 and COLO 4 during the EAT12 punch walk
A12: SAT14 | B12: Not Needed | C12: Harold | D12: Early January | F12: Not Confirmed | G12: 1/5: Katie reached out to David L. and Jerry B.
A13: SAT40 | B13: On Hold | C13: Harold | D13: Early January | F13: Not Confirmed | G13: 2/18: MSFT has not approved the CO. 1/5: Katie reached out to Kevin Shirley "Still waiting for MSFT to provide our dedicated fiber circuit for ISP connection" Kevin will update S2A when ready.
A14: CHI11 | B14: Complete | C14: Harold | D14: Late April | E14: 3/2, CHI11_Test Data (SP folder) | F14: Not Confirmed | G14: 4/13: Katie asked Harold for specific dates 3/17: Ron Swiercz sent full closeout package 3/3: Bram to review test data 2/26: Katie met with DAS contractor. He is sending the test data reports from the subcontractor to S2A. 2/11: Katie sent an email to Sultan Katrangi asking for update. Issues with the functionality of the DAS/Public safety systems at CHI10 which are preventing completion of CHI11 systems.
A15: CCO07 | B15: Not Needed | C15: TBD | D15: Mid-January | F15: Not Confirmed | G15: 1/13: HS response to Steve: Until DAS scopes are fully installed and tested, a site visit would be premature. At this time we are not going to schedule a visit 1/5: Katie reached out to Steve Baum. "The last word I had from S2 Advisors (possibly from Bram) was that no on site view was practical until the system was operational. If we need to have someone on site for a punch walk, we are planning on being on site the week of Jan 19 with Electrical/Mechanical being the first two days, Architectural, Security and LSS the last two days. Either group has room for S2 to join."
A16: YTO11/YTO40 | B16: Complete | C16: Harold | D16: July 23rd YTO11: Time: 8:30AM – Location project trailers YTO40: Time: 12:30PM – Location project trailers | F16: Confirmed | G16: 7/8: Harold will go to YTO11 first and then YTO40 6/26: Harold to complete DCAT form 6/16: Bell has completed installation and is ready for a site visit. Folders will be populated with test data at the end of the week. 6/10: Bell is currently on site and has not completed their scope as of today. ED will confirm with Bell and send us a heads up of when the work will be complete and ready for a site review, could be late June – stay tuned. 4/27: Expected site ready for a visit in early June. In anticipation of your eventual site visit to close out the Bell scope of work please see attached and fill out so we can get you security access into the turned over space. You can see my information filled out as a template, let me know if you have any questions or concerns, thanks.1/19: I’ve been told that the carrier (bell) has not proceeded with any work, and that they have not given any timeline on commencement. 1/5: Peter asked, "is the Bell Installation complete and should S2A be preparing to come out soon"
A17: PHX81 | B17: Rescheduled | C17: Bram | D17: March 23rd, 2026 | F17: Confirmed | G17: 3/3: Brian Gailfus sent pre-site visit instructions 2/18: Katie reached out to Sebastian Arias for DAS test and commissioning data. 1/26: Said this will most likely occur in March during leads meeting. 1/26: HP has pushed PHX82 punch to mid-February. More to come. I still haven’t heard if DAS testing will be complete. Let’s discuss in the leads meeting next Monday. 1/23: Waiting for Brian Gailfus to confirm second week of February. 1/12: Brian Gailfus: HP is asking to finish up PHX81 punch walks for Telecom, DAS/RoIP and Security.
A18: PHX82 | B18: On Hold | C18: Bram | D18: TBD (as of 3/17) | F18: Not Confirmed | G18: 2/20: Jesse B. said: PHX82 is still under construction at this time. Aiming to have Admin/COLO1/COLO2 install finished by mid to late March. 2/18: Visit the same time as PHX81? 1/26: Said this will most likely occur in March during leads meeting. 1/26: HP has pushed PHX82 punch to mid-February. More to come. I still haven’t heard if DAS testing will be complete. Let’s discuss in the leads meeting next Monday. 1/23: Waiting for Brian Gailfus to confirm second week of February. 1/12: Brian Gailfus said in the PHX81/82 leads meeting PHX82 would be ready for a site visit in early Feb
A19: PHX72 | B19: On Hold | C19: Bram | D19: March 25th, 2026 (can reschedule to March 24th) | E19: Receiving test data 3/17 | F19: Confirmed | G19: 3/6: Commissioning and the testing is supposed to be completed by March 16th. If so, that should be enough time to submit and review the needed information. Since zBeta schedules are as full as the rest of us, I recommend that we keep the March 25th date 2/20: Do not yet have test data. Ideally same trip at PHX81 and PHX82
A20: SAT80/81 | B20: On Hold | C20: Harold | D20: Mid June | E20: ProCore Portal | F20: Not Confirmed | G20: 6/10: Jesse replied: we have been on hold due to the VHF donor cable pathway out of the building, its not ready. 6/10: Katie followed up with Jesse B for test reports 4/27: the last time you all had representation on site for an Inspection was on 4/4/25 and at that time, SAT80 Admin & Colo1 were looked at. We have turned over to MS Colo2 and will be turning over Colo3 today. If you all need to get into the “Turned Over” areas then you all need to submit the names of the folks who will be going in the building under a DCAT, an MSOW may need to be submitted as well. Whoever goes in will also need to go through a MS Security Orientation. 4/23: E2 sent test data for SAT80/81 4/22: Katie reached out for GC contract 3/4: S2A needs to hold on a site visit until Mid to late April – that’s when E2Opitics will have completed the PSDAS.
A21: SAT15 | B21: Completed | C21: Harold | D21: 3/30-4/13 | E21: 3/2, SAT15_Test Data (SP folder) | F21: Not Confirmed | G21: 4/8: No longer needed. BW said we can sign off with accurate test results. 3/7: I can probably include COLO 4 as well in this walk, but early April is what we need to shoot for COLO 3. 3/4: Asking for next week
A22: SAT14 | B22: On Hold | C22: Harold | G22: 3/17: Asking for 3/23
A23: SAT14 | B23: Not Needed | C23: TBD | D23: Last week of May | E23: Requested | F23: Not Confirmed | G23: 4/27: Rene Palencia said: I just spoke with our superintendent and we are aiming to be ready for a walk the last week of May. 4/22: Katie reached out to Rene for DAS/ROIP test data report progress
A25: LYH10 / AVC43 / AVC01 / AVC09 | B25: Open | C25: Harold | F25: Not Confirmed | G25: BIR to use change order to look at public safety
A26: SAT40 | B26: Open | C26: Harold | F26: Not Confirmed | G26: 9/8: Katie reached out to KS for update. 6/16: Katie reached out to Kevin Shirley for ISP update
A27: FTY02 | B27: Open | C27: Bram | F27: Not Confirmed
A28: PHX72 | B28: Complete | C28: Harold | D28: July 7th | F28: Confirmed | G28: 6/22: Test report submittals complete
A29: YQB06 | B29: Complete | C29: Harold | D29: August 10th | F29: Confirmed | G29: 7/6: Vincent will also be there if technical questions arise.
A30: CCO07 | B30: On Hold | C30: Harold | F30: Not Confirmed | G30: 7/30: Check if Cx-ing is done
A31: CCO06 | B31: Open | C31: Bram | D31: Week of (or after) Sept 21 | F31: Not Confirmed | G31: 8/26: Currently cx is tracking for completion by 9/14. If these dates change. AHJ would would follow the next week 9/21. 7/14: Installation and Cx-ing should be done 17-21 Aug
A32: ATL06 | B32: On Hold | F32: Not Confirmed | G32: 7/30: Go to again? COLO turn-ups?
A33: IAD12-13 | B33: On Hold | F33: Not Confirmed | G33: 7/30: Check on status
A34: SAT80/81 | B34: Open | F34: Not Confirmed | G34: 9/8: Emailed Jesse Brierly for PSDAS update
